May 26 11:01:32 [Errno 111] Connection refused
Traceback (most recent call last):
  File "/usr/local/lib/python2.7/dist-packages/twisted/internet/defer.py", line 307, in addCallback
    callbackKeywords=kw)
  File "/usr/local/lib/python2.7/dist-packages/twisted/internet/defer.py", line 296, in addCallbacks
    self._runCallbacks()
  File "/usr/local/lib/python2.7/dist-packages/twisted/internet/defer.py", line 578, in _runCallbacks
    current.result = callback(current.result, *args, **kw)
  File "/usr/local/lib/python2.7/dist-packages/PyOPC/XDAServer.py", line 730, in CachedRead
    (IPH_READ,inOptions,outOptions))
--- <exception caught here> ---
  File "/usr/local/lib/python2.7/dist-packages/twisted/internet/defer.py", line 140, in maybeDeferred
    result = f(*args, **kw)
  File "/var/opc/PyOPC-Clients-Servers/servers/pw_relay/pw_relay_BasicXDAServer.py", line 64, in Read
    resp = (xda_cimore.Read(ItemContainer(ItemName = self.OPCItemDict[key].ItemName )))
  File "/usr/local/lib/python2.7/dist-packages/PyOPC/XDAClient.py", line 27, in operation
    result = getattr(self._portType,op)(x)
  File "/usr/local/lib/python2.7/dist-packages/PyOPC/OpcXmlDaSrv_services.py", line 102, in Read
    self.binding.Send(None, None, request, soapaction="http://opcfoundation.org/webservices/XMLDA/1.0/Read", **kw)
  File "/usr/local/lib/python2.7/dist-packages/ZSI/client.py", line 266, in Send
    self.h.connect()
  File "/usr/lib/python2.7/httplib.py", line 761, in connect
    self.timeout, self.source_address)
  File "/usr/lib/python2.7/socket.py", line 571, in create_connection
    raise err
socket.error: [Errno 111] Connection refused

May 26 11:01:34 [Errno 111] Connection refused
Traceback (most recent call last):
  File "/usr/local/lib/python2.7/dist-packages/twisted/internet/defer.py", line 307, in addCallback
    callbackKeywords=kw)
  File "/usr/local/lib/python2.7/dist-packages/twisted/internet/defer.py", line 296, in addCallbacks
    self._runCallbacks()
  File "/usr/local/lib/python2.7/dist-packages/twisted/internet/defer.py", line 578, in _runCallbacks
    current.result = callback(current.result, *args, **kw)
  File "/usr/local/lib/python2.7/dist-packages/PyOPC/XDAServer.py", line 730, in CachedRead
    (IPH_READ,inOptions,outOptions))
--- <exception caught here> ---
  File "/usr/local/lib/python2.7/dist-packages/twisted/internet/defer.py", line 140, in maybeDeferred
    result = f(*args, **kw)
  File "/var/opc/PyOPC-Clients-Servers/servers/pw_relay/pw_relay_BasicXDAServer.py", line 64, in Read
    resp = (xda_cimore.Read(ItemContainer(ItemName = self.OPCItemDict[key].ItemName )))
  File "/usr/local/lib/python2.7/dist-packages/PyOPC/XDAClient.py", line 27, in operation
    result = getattr(self._portType,op)(x)
  File "/usr/local/lib/python2.7/dist-packages/PyOPC/OpcXmlDaSrv_services.py", line 102, in Read
    self.binding.Send(None, None, request, soapaction="http://opcfoundation.org/webservices/XMLDA/1.0/Read", **kw)
  File "/usr/local/lib/python2.7/dist-packages/ZSI/client.py", line 266, in Send
    self.h.connect()
  File "/usr/lib/python2.7/httplib.py", line 761, in connect
    self.timeout, self.source_address)
  File "/usr/lib/python2.7/socket.py", line 571, in create_connection
    raise err
socket.error: [Errno 111] Connection refused

May 26 11:20:37 [Errno 111] Connection refused
Traceback (most recent call last):
  File "/usr/local/lib/python2.7/dist-packages/twisted/internet/defer.py", line 307, in addCallback
    callbackKeywords=kw)
  File "/usr/local/lib/python2.7/dist-packages/twisted/internet/defer.py", line 296, in addCallbacks
    self._runCallbacks()
  File "/usr/local/lib/python2.7/dist-packages/twisted/internet/defer.py", line 578, in _runCallbacks
    current.result = callback(current.result, *args, **kw)
  File "/usr/local/lib/python2.7/dist-packages/PyOPC/XDAServer.py", line 730, in CachedRead
    (IPH_READ,inOptions,outOptions))
--- <exception caught here> ---
  File "/usr/local/lib/python2.7/dist-packages/twisted/internet/defer.py", line 140, in maybeDeferred
    result = f(*args, **kw)
  File "/var/opc/PyOPC-Clients-Servers/servers/pw_relay/pw_relay_BasicXDAServer.py", line 64, in Read
    resp = (xda_cimore.Read(ItemContainer(ItemName = self.OPCItemDict[key].ItemName )))
  File "/usr/local/lib/python2.7/dist-packages/PyOPC/XDAClient.py", line 27, in operation
    result = getattr(self._portType,op)(x)
  File "/usr/local/lib/python2.7/dist-packages/PyOPC/OpcXmlDaSrv_services.py", line 102, in Read
    self.binding.Send(None, None, request, soapaction="http://opcfoundation.org/webservices/XMLDA/1.0/Read", **kw)
  File "/usr/local/lib/python2.7/dist-packages/ZSI/client.py", line 266, in Send
    self.h.connect()
  File "/usr/lib/python2.7/httplib.py", line 761, in connect
    self.timeout, self.source_address)
  File "/usr/lib/python2.7/socket.py", line 571, in create_connection
    raise err
socket.error: [Errno 111] Connection refused

May 26 12:17:35 [Errno 111] Connection refused
Traceback (most recent call last):
  File "/usr/local/lib/python2.7/dist-packages/twisted/internet/defer.py", line 307, in addCallback
    callbackKeywords=kw)
  File "/usr/local/lib/python2.7/dist-packages/twisted/internet/defer.py", line 296, in addCallbacks
    self._runCallbacks()
  File "/usr/local/lib/python2.7/dist-packages/twisted/internet/defer.py", line 578, in _runCallbacks
    current.result = callback(current.result, *args, **kw)
  File "/usr/local/lib/python2.7/dist-packages/PyOPC/XDAServer.py", line 730, in CachedRead
    (IPH_READ,inOptions,outOptions))
--- <exception caught here> ---
  File "/usr/local/lib/python2.7/dist-packages/twisted/internet/defer.py", line 140, in maybeDeferred
    result = f(*args, **kw)
  File "/var/opc/PyOPC-Clients-Servers/servers/pw_relay/pw_relay_BasicXDAServer.py", line 64, in Read
    resp = (xda_cimore.Read(ItemContainer(ItemName = self.OPCItemDict[key].ItemName )))
  File "/usr/local/lib/python2.7/dist-packages/PyOPC/XDAClient.py", line 27, in operation
    result = getattr(self._portType,op)(x)
  File "/usr/local/lib/python2.7/dist-packages/PyOPC/OpcXmlDaSrv_services.py", line 102, in Read
    self.binding.Send(None, None, request, soapaction="http://opcfoundation.org/webservices/XMLDA/1.0/Read", **kw)
  File "/usr/local/lib/python2.7/dist-packages/ZSI/client.py", line 266, in Send
    self.h.connect()
  File "/usr/lib/python2.7/httplib.py", line 761, in connect
    self.timeout, self.source_address)
  File "/usr/lib/python2.7/socket.py", line 571, in create_connection
    raise err
socket.error: [Errno 111] Connection refused

May 26 12:17:36 [Errno 111] Connection refused
Traceback (most recent call last):
  File "/usr/local/lib/python2.7/dist-packages/twisted/internet/defer.py", line 307, in addCallback
    callbackKeywords=kw)
  File "/usr/local/lib/python2.7/dist-packages/twisted/internet/defer.py", line 296, in addCallbacks
    self._runCallbacks()
  File "/usr/local/lib/python2.7/dist-packages/twisted/internet/defer.py", line 578, in _runCallbacks
    current.result = callback(current.result, *args, **kw)
  File "/usr/local/lib/python2.7/dist-packages/PyOPC/XDAServer.py", line 730, in CachedRead
    (IPH_READ,inOptions,outOptions))
--- <exception caught here> ---
  File "/usr/local/lib/python2.7/dist-packages/twisted/internet/defer.py", line 140, in maybeDeferred
    result = f(*args, **kw)
  File "/var/opc/PyOPC-Clients-Servers/servers/pw_relay/pw_relay_BasicXDAServer.py", line 64, in Read
    resp = (xda_cimore.Read(ItemContainer(ItemName = self.OPCItemDict[key].ItemName )))
  File "/usr/local/lib/python2.7/dist-packages/PyOPC/XDAClient.py", line 27, in operation
    result = getattr(self._portType,op)(x)
  File "/usr/local/lib/python2.7/dist-packages/PyOPC/OpcXmlDaSrv_services.py", line 102, in Read
    self.binding.Send(None, None, request, soapaction="http://opcfoundation.org/webservices/XMLDA/1.0/Read", **kw)
  File "/usr/local/lib/python2.7/dist-packages/ZSI/client.py", line 266, in Send
    self.h.connect()
  File "/usr/lib/python2.7/httplib.py", line 761, in connect
    self.timeout, self.source_address)
  File "/usr/lib/python2.7/socket.py", line 571, in create_connection
    raise err
socket.error: [Errno 111] Connection refused

May 26 12:17:37 [Errno 111] Connection refused
Traceback (most recent call last):
  File "/usr/local/lib/python2.7/dist-packages/twisted/internet/defer.py", line 307, in addCallback
    callbackKeywords=kw)
  File "/usr/local/lib/python2.7/dist-packages/twisted/internet/defer.py", line 296, in addCallbacks
    self._runCallbacks()
  File "/usr/local/lib/python2.7/dist-packages/twisted/internet/defer.py", line 578, in _runCallbacks
    current.result = callback(current.result, *args, **kw)
  File "/usr/local/lib/python2.7/dist-packages/PyOPC/XDAServer.py", line 730, in CachedRead
    (IPH_READ,inOptions,outOptions))
--- <exception caught here> ---
  File "/usr/local/lib/python2.7/dist-packages/twisted/internet/defer.py", line 140, in maybeDeferred
    result = f(*args, **kw)
  File "/var/opc/PyOPC-Clients-Servers/servers/pw_relay/pw_relay_BasicXDAServer.py", line 64, in Read
    resp = (xda_cimore.Read(ItemContainer(ItemName = self.OPCItemDict[key].ItemName )))
  File "/usr/local/lib/python2.7/dist-packages/PyOPC/XDAClient.py", line 27, in operation
    result = getattr(self._portType,op)(x)
  File "/usr/local/lib/python2.7/dist-packages/PyOPC/OpcXmlDaSrv_services.py", line 102, in Read
    self.binding.Send(None, None, request, soapaction="http://opcfoundation.org/webservices/XMLDA/1.0/Read", **kw)
  File "/usr/local/lib/python2.7/dist-packages/ZSI/client.py", line 266, in Send
    self.h.connect()
  File "/usr/lib/python2.7/httplib.py", line 761, in connect
    self.timeout, self.source_address)
  File "/usr/lib/python2.7/socket.py", line 571, in create_connection
    raise err
socket.error: [Errno 111] Connection refused

May 26 12:17:42 [Errno 111] Connection refused
Traceback (most recent call last):
  File "/usr/local/lib/python2.7/dist-packages/twisted/internet/defer.py", line 307, in addCallback
    callbackKeywords=kw)
  File "/usr/local/lib/python2.7/dist-packages/twisted/internet/defer.py", line 296, in addCallbacks
    self._runCallbacks()
  File "/usr/local/lib/python2.7/dist-packages/twisted/internet/defer.py", line 578, in _runCallbacks
    current.result = callback(current.result, *args, **kw)
  File "/usr/local/lib/python2.7/dist-packages/PyOPC/XDAServer.py", line 730, in CachedRead
    (IPH_READ,inOptions,outOptions))
--- <exception caught here> ---
  File "/usr/local/lib/python2.7/dist-packages/twisted/internet/defer.py", line 140, in maybeDeferred
    result = f(*args, **kw)
  File "/var/opc/PyOPC-Clients-Servers/servers/pw_relay/pw_relay_BasicXDAServer.py", line 64, in Read
    resp = (xda_cimore.Read(ItemContainer(ItemName = self.OPCItemDict[key].ItemName )))
  File "/usr/local/lib/python2.7/dist-packages/PyOPC/XDAClient.py", line 27, in operation
    result = getattr(self._portType,op)(x)
  File "/usr/local/lib/python2.7/dist-packages/PyOPC/OpcXmlDaSrv_services.py", line 102, in Read
    self.binding.Send(None, None, request, soapaction="http://opcfoundation.org/webservices/XMLDA/1.0/Read", **kw)
  File "/usr/local/lib/python2.7/dist-packages/ZSI/client.py", line 266, in Send
    self.h.connect()
  File "/usr/lib/python2.7/httplib.py", line 761, in connect
    self.timeout, self.source_address)
  File "/usr/lib/python2.7/socket.py", line 571, in create_connection
    raise err
socket.error: [Errno 111] Connection refused

May 26 12:17:42 [Errno 111] Connection refused
Traceback (most recent call last):
  File "/usr/local/lib/python2.7/dist-packages/twisted/internet/defer.py", line 307, in addCallback
    callbackKeywords=kw)
  File "/usr/local/lib/python2.7/dist-packages/twisted/internet/defer.py", line 296, in addCallbacks
    self._runCallbacks()
  File "/usr/local/lib/python2.7/dist-packages/twisted/internet/defer.py", line 578, in _runCallbacks
    current.result = callback(current.result, *args, **kw)
  File "/usr/local/lib/python2.7/dist-packages/PyOPC/XDAServer.py", line 730, in CachedRead
    (IPH_READ,inOptions,outOptions))
--- <exception caught here> ---
  File "/usr/local/lib/python2.7/dist-packages/twisted/internet/defer.py", line 140, in maybeDeferred
    result = f(*args, **kw)
  File "/var/opc/PyOPC-Clients-Servers/servers/pw_relay/pw_relay_BasicXDAServer.py", line 64, in Read
    resp = (xda_cimore.Read(ItemContainer(ItemName = self.OPCItemDict[key].ItemName )))
  File "/usr/local/lib/python2.7/dist-packages/PyOPC/XDAClient.py", line 27, in operation
    result = getattr(self._portType,op)(x)
  File "/usr/local/lib/python2.7/dist-packages/PyOPC/OpcXmlDaSrv_services.py", line 102, in Read
    self.binding.Send(None, None, request, soapaction="http://opcfoundation.org/webservices/XMLDA/1.0/Read", **kw)
  File "/usr/local/lib/python2.7/dist-packages/ZSI/client.py", line 266, in Send
    self.h.connect()
  File "/usr/lib/python2.7/httplib.py", line 761, in connect
    self.timeout, self.source_address)
  File "/usr/lib/python2.7/socket.py", line 571, in create_connection
    raise err
socket.error: [Errno 111] Connection refused

